<?xml version="1.0" encoding="UTF-8"?>
<testng-results ignored="0" total="9" passed="6" failed="3" skipped="0">
  <reporter-output>
  </reporter-output>
  <suite started-at="2023-04-13T20:50:40 MDT" name="Default suite" finished-at="2023-04-13T20:52:21 MDT" duration-ms="101287">
    <groups>
    </groups>
    <test started-at="2023-04-13T20:50:40 MDT" name="Default test" finished-at="2023-04-13T20:52:21 MDT" duration-ms="101287">
      <class name="assessment.AssessmentTests">
        <test-method signature="add_Two_Items_to_Cart()[pri:0, instance:assessment.AssessmentTests@6497b078]" started-at="2023-04-13T20:50:40 MDT" name="add_Two_Items_to_Cart" finished-at="2023-04-13T20:50:56 MDT" duration-ms="15706" status="PASS">
          <reporter-output>
          </reporter-output>
        </test-method> <!-- add_Two_Items_to_Cart -->
        <test-method signature="createAccount_Account_Already_Exists()[pri:0, instance:assessment.AssessmentTests@6497b078]" started-at="2023-04-13T20:50:56 MDT" name="createAccount_Account_Already_Exists" finished-at="2023-04-13T20:51:05 MDT" duration-ms="9376" status="PASS">
          <reporter-output>
          </reporter-output>
        </test-method> <!-- createAccount_Account_Already_Exists -->
        <test-method signature="createAccount_Account_Does_Not_Exist_Yet()[pri:0, instance:assessment.AssessmentTests@6497b078]" started-at="2023-04-13T20:51:05 MDT" name="createAccount_Account_Does_Not_Exist_Yet" finished-at="2023-04-13T20:51:15 MDT" duration-ms="9603" status="PASS">
          <reporter-output>
          </reporter-output>
        </test-method> <!-- createAccount_Account_Does_Not_Exist_Yet -->
        <test-method signature="createAccount_Cancel_Create_Account()[pri:0, instance:assessment.AssessmentTests@6497b078]" started-at="2023-04-13T20:51:15 MDT" name="createAccount_Cancel_Create_Account" finished-at="2023-04-13T20:51:24 MDT" duration-ms="9200" status="PASS">
          <reporter-output>
          </reporter-output>
        </test-method> <!-- createAccount_Cancel_Create_Account -->
        <test-method signature="delete_One_Item_from_Cart_With_Two_Items()[pri:0, instance:assessment.AssessmentTests@6497b078]" started-at="2023-04-13T20:51:24 MDT" name="delete_One_Item_from_Cart_With_Two_Items" finished-at="2023-04-13T20:51:36 MDT" duration-ms="12363" status="FAIL">
          <exception class="java.lang.AssertionError">
            <message>
              <![CDATA[expected [1] but found [2]]]>
            </message>
            <full-stacktrace>
              <![CDATA[java.lang.AssertionError: expected [1] but found [2]
at org.testng.Assert.fail(Assert.java:99)
at org.testng.Assert.failNotEquals(Assert.java:1037)
at org.testng.Assert.assertEqualsImpl(Assert.java:140)
at org.testng.Assert.assertEquals(Assert.java:122)
at org.testng.Assert.assertEquals(Assert.java:907)
at org.testng.Assert.assertEquals(Assert.java:917)
at assessment.AssessmentTests.delete_One_Item_from_Cart_With_Two_Items(AssessmentTests.java:448)
at java.base/jdk.internal.reflect.NativeMethodAccessorImpl.invoke0(Native Method)
at java.base/jdk.internal.reflect.NativeMethodAccessorImpl.invoke(NativeMethodAccessorImpl.java:64)
at java.base/jdk.internal.reflect.DelegatingMethodAccessorImpl.invoke(DelegatingMethodAccessorImpl.java:43)
at java.base/java.lang.reflect.Method.invoke(Method.java:564)
at org.testng.internal.MethodInvocationHelper.invokeMethod(MethodInvocationHelper.java:133)
at org.testng.internal.TestInvoker.invokeMethod(TestInvoker.java:598)
at org.testng.internal.TestInvoker.invokeTestMethod(TestInvoker.java:173)
at org.testng.internal.MethodRunner.runInSequence(MethodRunner.java:46)
at org.testng.internal.TestInvoker$MethodInvocationAgent.invoke(TestInvoker.java:824)
at org.testng.internal.TestInvoker.invokeTestMethods(TestInvoker.java:146)
at org.testng.internal.TestMethodWorker.invokeTestMethods(TestMethodWorker.java:146)
at org.testng.internal.TestMethodWorker.run(TestMethodWorker.java:128)
at java.base/java.util.ArrayList.forEach(ArrayList.java:1511)
at org.testng.TestRunner.privateRun(TestRunner.java:794)
at org.testng.TestRunner.run(TestRunner.java:596)
at org.testng.SuiteRunner.runTest(SuiteRunner.java:377)
at org.testng.SuiteRunner.runSequentially(SuiteRunner.java:371)
at org.testng.SuiteRunner.privateRun(SuiteRunner.java:332)
at org.testng.SuiteRunner.run(SuiteRunner.java:276)
at org.testng.SuiteRunnerWorker.runSuite(SuiteRunnerWorker.java:53)
at org.testng.SuiteRunnerWorker.run(SuiteRunnerWorker.java:96)
at org.testng.TestNG.runSuitesSequentially(TestNG.java:1212)
at org.testng.TestNG.runSuitesLocally(TestNG.java:1134)
at org.testng.TestNG.runSuites(TestNG.java:1063)
at org.testng.TestNG.run(TestNG.java:1031)
at org.testng.remote.AbstractRemoteTestNG.run(AbstractRemoteTestNG.java:115)
at org.testng.remote.RemoteTestNG.initAndRun(RemoteTestNG.java:251)
at org.testng.remote.RemoteTestNG.main(RemoteTestNG.java:77)
]]>
            </full-stacktrace>
          </exception> <!-- java.lang.AssertionError -->
          <reporter-output>
          </reporter-output>
        </test-method> <!-- delete_One_Item_from_Cart_With_Two_Items -->
        <test-method signature="delete_Two_Items_from_Cart()[pri:0, instance:assessment.AssessmentTests@6497b078]" started-at="2023-04-13T20:51:36 MDT" name="delete_Two_Items_from_Cart" finished-at="2023-04-13T20:51:49 MDT" duration-ms="12303" status="FAIL">
          <exception class="java.lang.AssertionError">
            <message>
              <![CDATA[expected [true] but found [false]]]>
            </message>
            <full-stacktrace>
              <![CDATA[java.lang.AssertionError: expected [true] but found [false]
at org.testng.Assert.fail(Assert.java:99)
at org.testng.Assert.failNotEquals(Assert.java:1037)
at org.testng.Assert.assertTrue(Assert.java:45)
at org.testng.Assert.assertTrue(Assert.java:55)
at assessment.AssessmentTests.delete_Two_Items_from_Cart(AssessmentTests.java:361)
at java.base/jdk.internal.reflect.NativeMethodAccessorImpl.invoke0(Native Method)
at java.base/jdk.internal.reflect.NativeMethodAccessorImpl.invoke(NativeMethodAccessorImpl.java:64)
at java.base/jdk.internal.reflect.DelegatingMethodAccessorImpl.invoke(DelegatingMethodAccessorImpl.java:43)
at java.base/java.lang.reflect.Method.invoke(Method.java:564)
at org.testng.internal.MethodInvocationHelper.invokeMethod(MethodInvocationHelper.java:133)
at org.testng.internal.TestInvoker.invokeMethod(TestInvoker.java:598)
at org.testng.internal.TestInvoker.invokeTestMethod(TestInvoker.java:173)
at org.testng.internal.MethodRunner.runInSequence(MethodRunner.java:46)
at org.testng.internal.TestInvoker$MethodInvocationAgent.invoke(TestInvoker.java:824)
at org.testng.internal.TestInvoker.invokeTestMethods(TestInvoker.java:146)
at org.testng.internal.TestMethodWorker.invokeTestMethods(TestMethodWorker.java:146)
at org.testng.internal.TestMethodWorker.run(TestMethodWorker.java:128)
at java.base/java.util.ArrayList.forEach(ArrayList.java:1511)
at org.testng.TestRunner.privateRun(TestRunner.java:794)
at org.testng.TestRunner.run(TestRunner.java:596)
at org.testng.SuiteRunner.runTest(SuiteRunner.java:377)
at org.testng.SuiteRunner.runSequentially(SuiteRunner.java:371)
at org.testng.SuiteRunner.privateRun(SuiteRunner.java:332)
at org.testng.SuiteRunner.run(SuiteRunner.java:276)
at org.testng.SuiteRunnerWorker.runSuite(SuiteRunnerWorker.java:53)
at org.testng.SuiteRunnerWorker.run(SuiteRunnerWorker.java:96)
at org.testng.TestNG.runSuitesSequentially(TestNG.java:1212)
at org.testng.TestNG.runSuitesLocally(TestNG.java:1134)
at org.testng.TestNG.runSuites(TestNG.java:1063)
at org.testng.TestNG.run(TestNG.java:1031)
at org.testng.remote.AbstractRemoteTestNG.run(AbstractRemoteTestNG.java:115)
at org.testng.remote.RemoteTestNG.initAndRun(RemoteTestNG.java:251)
at org.testng.remote.RemoteTestNG.main(RemoteTestNG.java:77)
]]>
            </full-stacktrace>
          </exception> <!-- java.lang.AssertionError -->
          <reporter-output>
          </reporter-output>
        </test-method> <!-- delete_Two_Items_from_Cart -->
        <test-method signature="logIn()[pri:0, instance:assessment.AssessmentTests@6497b078]" started-at="2023-04-13T20:51:49 MDT" name="logIn" finished-at="2023-04-13T20:51:59 MDT" duration-ms="10697" status="PASS">
          <reporter-output>
          </reporter-output>
        </test-method> <!-- logIn -->
        <test-method signature="logOut()[pri:0, instance:assessment.AssessmentTests@6497b078]" started-at="2023-04-13T20:51:59 MDT" name="logOut" finished-at="2023-04-13T20:52:10 MDT" duration-ms="10760" status="PASS">
          <reporter-output>
          </reporter-output>
        </test-method> <!-- logOut -->
        <test-method signature="number_Of_Items_In_Cart()[pri:0, instance:assessment.AssessmentTests@6497b078]" started-at="2023-04-13T20:52:10 MDT" name="number_Of_Items_In_Cart" finished-at="2023-04-13T20:52:21 MDT" duration-ms="11201" status="FAIL">
          <exception class="java.lang.AssertionError">
            <message>
              <![CDATA[expected [2] but found [1]]]>
            </message>
            <full-stacktrace>
              <![CDATA[java.lang.AssertionError: expected [2] but found [1]
at org.testng.Assert.fail(Assert.java:99)
at org.testng.Assert.failNotEquals(Assert.java:1037)
at org.testng.Assert.assertEqualsImpl(Assert.java:140)
at org.testng.Assert.assertEquals(Assert.java:122)
at org.testng.Assert.assertEquals(Assert.java:907)
at org.testng.Assert.assertEquals(Assert.java:917)
at assessment.AssessmentTests.number_Of_Items_In_Cart(AssessmentTests.java:517)
at java.base/jdk.internal.reflect.NativeMethodAccessorImpl.invoke0(Native Method)
at java.base/jdk.internal.reflect.NativeMethodAccessorImpl.invoke(NativeMethodAccessorImpl.java:64)
at java.base/jdk.internal.reflect.DelegatingMethodAccessorImpl.invoke(DelegatingMethodAccessorImpl.java:43)
at java.base/java.lang.reflect.Method.invoke(Method.java:564)
at org.testng.internal.MethodInvocationHelper.invokeMethod(MethodInvocationHelper.java:133)
at org.testng.internal.TestInvoker.invokeMethod(TestInvoker.java:598)
at org.testng.internal.TestInvoker.invokeTestMethod(TestInvoker.java:173)
at org.testng.internal.MethodRunner.runInSequence(MethodRunner.java:46)
at org.testng.internal.TestInvoker$MethodInvocationAgent.invoke(TestInvoker.java:824)
at org.testng.internal.TestInvoker.invokeTestMethods(TestInvoker.java:146)
at org.testng.internal.TestMethodWorker.invokeTestMethods(TestMethodWorker.java:146)
at org.testng.internal.TestMethodWorker.run(TestMethodWorker.java:128)
at java.base/java.util.ArrayList.forEach(ArrayList.java:1511)
at org.testng.TestRunner.privateRun(TestRunner.java:794)
at org.testng.TestRunner.run(TestRunner.java:596)
at org.testng.SuiteRunner.runTest(SuiteRunner.java:377)
at org.testng.SuiteRunner.runSequentially(SuiteRunner.java:371)
at org.testng.SuiteRunner.privateRun(SuiteRunner.java:332)
at org.testng.SuiteRunner.run(SuiteRunner.java:276)
at org.testng.SuiteRunnerWorker.runSuite(SuiteRunnerWorker.java:53)
at org.testng.SuiteRunnerWorker.run(SuiteRunnerWorker.java:96)
at org.testng.TestNG.runSuitesSequentially(TestNG.java:1212)
at org.testng.TestNG.runSuitesLocally(TestNG.java:1134)
at org.testng.TestNG.runSuites(TestNG.java:1063)
at org.testng.TestNG.run(TestNG.java:1031)
at org.testng.remote.AbstractRemoteTestNG.run(AbstractRemoteTestNG.java:115)
at org.testng.remote.RemoteTestNG.initAndRun(RemoteTestNG.java:251)
at org.testng.remote.RemoteTestNG.main(RemoteTestNG.java:77)
]]>
            </full-stacktrace>
          </exception> <!-- java.lang.AssertionError -->
          <reporter-output>
          </reporter-output>
        </test-method> <!-- number_Of_Items_In_Cart -->
      </class> <!-- assessment.AssessmentTests -->
    </test> <!-- Default test -->
  </suite> <!-- Default suite -->
</testng-results>
